Workbook

Sheet Project Info
B1: PROJECT EXECUTION – GANTT CHART
B2: Project Info › Tasks › Gantt › Holidays – everything is linked; fill the yellow cells only
B4: PROJECT DETAILS | E4: SCHEDULE HEALTH (auto-calculated)
B5: Project Name | C5: 1.8M C-Band Antenna System – 500 Sets | E5: Planned Finish (baseline) | F5: =IF(COUNT(Tasks!$R$11:$R$310)=0,"",MAX(Tasks!$R$11:$R$310)) -> 46500
B6: Client Name | C6: <Client name> | E6: Forecast Finish (incl. delays) | F6: =IF(COUNT(Tasks!$T$11:$T$310)=0,"",MAX(Tasks!$T$11:$T$310)) -> 46500
B7: Project Manager | C7: <Project manager> | E7: Target Completion Date | F7: =IF(C10="","",C10) -> 46500
B8: Project Code / Reference | C8: PRJ-2026-001 | E8: Delay vs TARGET (working days) | F8: =IF(OR(F6="",F7=""),"",IF(F6>=F7,NETWORKDAYS.INTL(F7,F6,'Project Info'!$H$12,Holidays!$A$6:$A$205)-1,-(NETWORKDAYS.INTL(F6,F7,'Project Info'!$H$12,Holidays!$A$6:$A$205)-1))) -> 0
B9: Project Start Date | C9: 46310 | E9: Delay vs PLAN (working days) | F9: =IF(OR(F5="",F6=""),"",IF(F6>=F5,NETWORKDAYS.INTL(F5,F6,'Project Info'!$H$12,Holidays!$A$6:$A$205)-1,-(NETWORKDAYS.INTL(F6,F5,'Project Info'!$H$12,Holidays!$A$6:$A$205)-1))) -> 0
B10: Target Completion Date | C10: 46500 | E10: Overall % Complete (duration weighted) | F10: =IF(SUM(Tasks!$J$11:$J$310)=0,"",SUM(Tasks!$AH$11:$AH$310)/SUM(Tasks!$J$11:$J$310)) -> 0
B11: Status (Report) Date | C11: =TODAY() -> 46303 | E11: Calendar days late vs Target | F11: =IF(OR(F6="",F7=""),"",F6-F7) -> 0
B12: Weekly Off | C12: Sunday only | H12: =IF(C12="Sunday only",11,IF(C12="Friday & Saturday",7,1)) -> 11
B13: Gantt View (set on Gantt sheet) | C13: =Gantt!B2 -> Week
B15: =IF(F8="","Add tasks on the Tasks sheet to see project health",IF(F8>0,"⚠ PROJECT DELAYED: forecast finish "&TEXT(F6,"dd-mmm-yyyy")&" is "&F8&" working day(s) after target "&TEXT(F7,"dd-mmm-yyyy"),IF(F9>0,"⚡ AT RISK: within target, but forecast finish is "&F9&" working day(s) later than plan","✔ ON TRACK: forecast finish "&TEXT(F6,"dd-mmm-yyyy")&" meets target "&TEXT(F7,"dd-mmm-yyyy")))) -> ✔ ON TRACK: forecast finish 23-Apr-2027 meets target 23-Apr-2027
B17: STATUS BY COMPONENT (tasks whose name starts with the text in column B)
B18: Component (name prefix) | C18: Planned Finish | E18: Forecast Finish | F18: Delay vs Plan (wd) | G18: % Complete
B19: REFLECTOR | C19: =IF(OR($B19="",COUNTIF(Tasks!$B$11:$B$310,$B19&"*")=0),"",SUMPRODUCT(MAX((LEFT(Tasks!$B$11:$B$310,LEN($B19))=$B19)*Tasks!$AI$11:$AI$310))) -> 46450 | E19: =IF(OR($B19="",COUNTIF(Tasks!$B$11:$B$310,$B19&"*")=0),"",SUMPRODUCT(MAX((LEFT(Tasks!$B$11:$B$310,LEN($B19))=$B19)*Tasks!$AJ$11:$AJ$310))) -> 46450 | F19: =IF(OR(C19="",E19=""),"",IF(E19>=C19,NETWORKDAYS.INTL(C19,E19,'Project Info'!$H$12,Holidays!$A$6:$A$205)-1,-(NETWORKDAYS.INTL(E19,C19,'Project Info'!$H$12,Holidays!$A$6:$A$205)-1))) -> 0 | G19: =IF(OR($B19="",SUMIFS(Tasks!$J$11:$J$310,Tasks!$B$11:$B$310,$B19&"*")=0),"",SUMIFS(Tasks!$AH$11:$AH$310,Tasks!$B$11:$B$310,$B19&"*")/SUMIFS(Tasks!$J$11:$J$310,Tasks!$B$11:$B$310,$B19&"*")) -> 0
B20: FEED | C20: =IF(OR($B20="",COUNTIF(Tasks!$B$11:$B$310,$B20&"*")=0),"",SUMPRODUCT(MAX((LEFT(Tasks!$B$11:$B$310,LEN($B20))=$B20)*Tasks!$AI$11:$AI$310))) -> 46500 | E20: =IF(OR($B20="",COUNTIF(Tasks!$B$11:$B$310,$B20&"*")=0),"",SUMPRODUCT(MAX((LEFT(Tasks!$B$11:$B$310,LEN($B20))=$B20)*Tasks!$AJ$11:$AJ$310))) -> 46500 | F20: =IF(OR(C20="",E20=""),"",IF(E20>=C20,NETWORKDAYS.INTL(C20,E20,'Project Info'!$H$12,Holidays!$A$6:$A$205)-1,-(NETWORKDAYS.INTL(E20,C20,'Project Info'!$H$12,Holidays!$A$6:$A$205)-1))) -> 0 | G20: =IF(OR($B20="",SUMIFS(Tasks!$J$11:$J$310,Tasks!$B$11:$B$310,$B20&"*")=0),"",SUMIFS(Tasks!$AH$11:$AH$310,Tasks!$B$11:$B$310,$B20&"*")/SUMIFS(Tasks!$J$11:$J$310,Tasks!$B$11:$B$310,$B20&"*")) -> 0
B21: METAL | C21: =IF(OR($B21="",COUNTIF(Tasks!$B$11:$B$310,$B21&"*")=0),"",SUMPRODUCT(MAX((LEFT(Tasks!$B$11:$B$310,LEN($B21))=$B21)*Tasks!$AI$11:$AI$310))) -> 46403 | E21: =IF(OR($B21="",COUNTIF(Tasks!$B$11:$B$310,$B21&"*")=0),"",SUMPRODUCT(MAX((LEFT(Tasks!$B$11:$B$310,LEN($B21))=$B21)*Tasks!$AJ$11:$AJ$310))) -> 46403 | F21: =IF(OR(C21="",E21=""),"",IF(E21>=C21,NETWORKDAYS.INTL(C21,E21,'Project Info'!$H$12,Holidays!$A$6:$A$205)-1,-(NETWORKDAYS.INTL(E21,C21,'Project Info'!$H$12,Holidays!$A$6:$A$205)-1))) -> 0 | G21: =IF(OR($B21="",SUMIFS(Tasks!$J$11:$J$310,Tasks!$B$11:$B$310,$B21&"*")=0),"",SUMIFS(Tasks!$AH$11:$AH$310,Tasks!$B$11:$B$310,$B21&"*")/SUMIFS(Tasks!$J$11:$J$310,Tasks!$B$11:$B$310,$B21&"*")) -> 0
B23: TASK STATISTICS | E23: HOW TO USE
B24: Total Tasks | C24: =COUNTIF(Tasks!$B$11:$B$310,"?*") -> 30 | E24: 1. Fill the yellow Project Details: start / target / report date and the Weekly Off.
B25: Completed | C25: =COUNTIF(Tasks!$AE$11:$AE$310,"Completed") -> 0 | E25: 2. Holidays sheet: list non-working dates.
B26: In Progress | C26: =COUNTIF(Tasks!$AE$11:$AE$310,"In Progress") -> 0 | E26: 3. Tasks sheet: Task Name + Duration (working days) + predecessor ID(s). Link FS = after predecessor ends (default); SS = starts n days after it starts; FF = ends n days after it ends. Lag in working days.
B27: Not Started / On Hold | C27: =COUNTIF(Tasks!$AE$11:$AE$310,"Not Started")+COUNTIF(Tasks!$AE$11:$AE$310,"On Hold") -> 30 | E27: 4. Update progress: Status, Actual Start/End, % Complete. Use Revised Duration when you expect an overshoot.
B28: Tasks Overshooting Duration | C28: =COUNTIF(Tasks!$V$11:$V$310,">0") -> 0 | E28: 5. Gantt sheet: pick Day / Week / Month in cell B2; scroll the timeline with C2.
B29: Tasks Affected by Others' Delay | C29: =COUNTIF(Tasks!$Y$11:$Y$310,"Delayed*") -> 0 | E29: 6. 300 task rows are pre-built; copy the last row down to add more.
B30: Largest Overshoot (task) | C30: =IF(MAX(Tasks!$V$11:$V$310)<=0,"None",INDEX(Tasks!$B$11:$B$310,MATCH(MAX(Tasks!$V$11:$V$310),Tasks!$V$11:$V$310,0))&" (+"&MAX(Tasks!$V$11:$V$310)&" d)") -> None | E30: 7. Avoid circular links (A waits for B and B waits for A).
B31: Total Planned Task-Days | C31: =SUM(Tasks!$J$11:$J$310) -> 432 | E31: Yellow cells = input · white cells = formulas (do not overwrite).
B33: COLOUR LEGEND
B34: Completed | C34: Task finished (bar portion within planned duration)
B35: In Progress | C35: Task started, not finished
B36: Not Started | C36: Scheduled, not yet begun
B37: On Hold | C37: Task paused
B38: Overshoot | C38: Time used beyond the planned DURATION (task ran / is expected to run over)
B39: Delayed / Affected | C39: Start pushed out by a late predecessor or by the status date (see 'Impact' column)
B40: Planned (not used) | C40: Planned time no longer used (finished early / started late)
B41: Weekly off | C41: Weekly-off day (Day view)
B42: Holiday | C42: Dates from the Holidays sheet (pink header in Week/Month view = holiday inside period)
B43: Status Date | C43: Column of the report date set above
B44: ▶ Start | C44: First day of a task with no predecessor
B45: ↳ Dependent start | C45: First day of a task that waits for a predecessor
...

Sheet Tasks
A1: ="TASK LIST – "&'Project Info'!C5&" | Client: "&'Project Info'!C6 -> TASK LIST – 1.8M C-Band Antenna System – 500 Sets | Client: <Client name>
A2: Type in the YELLOW cells only. Link: FS = starts after predecessor ends (blank = FS) · SS = starts n days after it starts · FF = ends n days after it ends. Lag / duration are WORKING days (weekly-off & holidays skipped).
A4: ='Project Info'!$B$15 -> ✔ ON TRACK: forecast finish 23-Apr-2027 meets target 23-Apr-2027
A5: ="Planned finish: "&IF('Project Info'!F5="","-",TEXT('Project Info'!F5,"dd-mmm-yy"))&" | Forecast finish: "&IF('Project Info'!F6="","-",TEXT('Project Info'!F6,"dd-mmm-yy"))&" | Target: "&IF('Project Info'!F7="","-",TEXT('Project Info'!F7,"dd-mmm-yy"))&" | Overall progress: "&IF('Project Info'!F10="","-",TEXT('Project Info'!F10,"0%"))&" | Status date: "&IF('Project Info'!$C$11="","-",TEXT('Project Info'!$C$11,"dd-mmm-yy")) -> Planned finish: 23-Apr-27 | Forecast finish: 23-Apr-27 | Target: 23-Apr-27 | Overall progress: 0% | Status date: 08-Oct-26
A9: ① TASK ENTRY | L9: ② STATUS UPDATE | Q9: ③ SCHEDULE & ANALYSIS (automatic) | AA9: helper
A10: ID | B10: Task Name | C10: Owner | D10: Pred. 1 (ID) | E10: Link 1 (FS/SS/FF) | F10: Lag 1 (days) | G10: Pred. 2 (ID) | H10: Link 2 (FS/SS/FF) | I10: Lag 2 (days) | J10: Duration (work days) | K10: Start No Earlier Than (optional) | L10: Status | M10: Actual Start | N10: Actual End | O10: % Complete | P10: Revised Duration (if overshoot) | Q10: Planned Start | R10: Planned End | S10: Forecast / Actual Start | T10: Forecast / Actual End | U10: Forecast / Actual Duration | V10: Duration Variance (days) | W10: Duration Status | X10: End Slip vs Plan (days) | Y10: Impact (affected by) | Z10: No. of Dependent Links | AA10: class | AB10: has pred | AC10: pred1 slip | AD10: pred2 slip | AE10: eff status | AF10: eff % | AG10: end if no overshoot | AH10: weighted done | AI10: planned end (num) | AJ10: fcst end (num)
A11: =IF($B11="","",ROW()-10) -> 1 | B11: REFLECTOR | Finalize 1.8M mold design | C11: Design | J11: 7 | L11: Not Started | Q11: =IF(OR($B11="",'Project Info'!$C$9=""),"",WORKDAY.INTL(MAX('Project Info'!$C$9,N($K11),IF($D11="",0,N(IFERROR(IF($E11="SS",WORKDAY.INTL(INDEX($Q$11:$Q$310,MATCH($D11,$A$11:$A$310,0)),N($F11),'Project Info'!$H$12,Holidays!$A$6:$A$205),IF($E11="FF",WORKDAY.INTL(INDEX($R$11:$R$310,MATCH($D11,$A$11:$A$310,0)),N($F11)-MAX(1,N($J11))+1,'Project Info'!$H$12,Holidays!$A$6:$A$205),WORKDAY.INTL(INDEX($R$11:$R$310,MATCH($D11,$A$11:$A$310,0)),1+N($F11),'Project Info'!$H$12,Holidays!$A$6:$A$205))),0))),IF($G11="",0,N(IFERROR(IF($H11="SS",WORKDAY.INTL(INDEX($Q$11:$Q$310,MATCH($G11,$A$11:$A$310,0)),N($I11),'Project Info'!$H$12,Holidays!$A$6:$A$205),IF($H11="FF",WORKDAY.INTL(INDEX($R$11:$R$310,MATCH($G11,$A$11:$A$310,0)),N($I11)-MAX(1,N($J11))+1,'Project Info'!$H$12,Holidays!$A$6:$A$205),WORKDAY.INTL(INDEX($R$11:$R$310,MATCH($G11,$A$11:$A$310,0)),1+N($I11),'Project Info'!$H$12,Holidays!$A$6:$A$205))),0))))-1,1,'Project Info'!$H$12,Holidays!$A$6:$A$205)) -> 46310 | R11: =IF(OR($Q11="",NOT(ISNUMBER($J11))),"",WORKDAY.INTL($Q11,MAX(1,$J11)-1,'Project Info'!$H$12,Holidays!$A$6:$A$205)) -> 46318 | S11: =IF($Q11="","",IF(ISNUMBER($M11),$M11,WORKDAY.INTL(MAX($Q11,IF($D11="",0,N(IFERROR(IF($E11="SS",WORKDAY.INTL(INDEX($S$11:$S$310,MATCH($D11,$A$11:$A$310,0)),N($F11),'Project Info'!$H$12,Holidays!$A$6:$A$205),IF($E11="FF",WORKDAY.INTL(INDEX($T$11:$T$310,MATCH($D11,$A$11:$A$310,0)),N($F11)-MAX(1,IF(ISNUMBER($P11),$P11,N($J11)))+1,'Project Info'!$H$12,Holidays!$A$6:$A$205),WORKDAY.INTL(INDEX($T$11:$T$310,MATCH($D11,$A$11:$A$310,0)),1+N($F11),'Project Info'!$H$12,Holidays!$A$6:$A$205))),0))),IF($G11="",0,N(IFERROR(IF($H11="SS",WORKDAY.INTL(INDEX($S$11:$S$310,MATCH($G11,$A$11:$A$310,0)),N($I11),'Project Info'!$H$12,Holidays!$A$6:$A$205),IF($H11="FF",WORKDAY.INTL(INDEX($T$11:$T$310,MATCH($G11,$A$11:$A$310,0)),N($I11)-MAX(1,IF(ISNUMBER($P11),$P11,N($J11)))+1,'Project Info'!$H$12,Holidays!$A$6:$A$205),WORKDAY.INTL(INDEX($T$11:$T$310,MATCH($G11,$A$11:$A$310,0)),1+N($I11),'Project Info'!$H$12,Holidays!$A$6:$A$205))),0))),IF($AE11="Completed",0,N('Project Info'!$C$11)))-1,1,'Project Info'!$H$12,Holidays!$A$6:$A$205))) -> 46310 | T11: =IF(OR($S11="",$U11=""),"",IF(ISNUMBER($N11),$N11,WORKDAY.INTL($S11,$U11-1,'Project Info'!$H$12,Holidays!$A$6:$A$205))) -> 46318 | U11: =IF(OR($S11="",NOT(ISNUMBER($J11))),"",IF(ISNUMBER($N11),MAX(1,NETWORKDAYS.INTL($S11,$N11,'Project Info'!$H$12,Holidays!$A$6:$A$205)),MAX(1,IF(ISNUMBER($P11),$P11,$J11),IF(ISNUMBER($M11),NETWORKDAYS.INTL($M11,N('Project Info'!$C$11),'Project Info'!$H$12,Holidays!$A$6:$A$205),0)))) -> 7 | V11: =IF($U11="","",$U11-MAX(1,$J11)) -> 0 | W11: =IF($B11="","",IF($U11="","Enter Duration",IF($AE11="Completed",IF(NOT(ISNUMBER($N11)),"Completed - enter Actual End",IF($V11>0,"Completed - Overshoot",IF($V11<0,"Completed - Early","Completed - On Time"))),IF($AE11="On Hold","On Hold",IF($AE11="In Progress",IF($V11>0,"In Progress - Overshooting","In Progress - On Track"),IF($S11>$Q11,"Delayed Start","Not Started")))))) -> Not Started | X11: =IF(OR(NOT(ISNUMBER($R11)),NOT(ISNUMBER($T11))),"",IF($T11>=$R11,NETWORKDAYS.INTL($R11,$T11,'Project Info'!$H$12,Holidays!$A$6:$A$205)-1,-(NETWORKDAYS.INTL($T11,$R11,'Project Info'!$H$12,Holidays!$A$6:$A$205)-1))) -> 0 | Y11: =IF($B11="","",IF(AND(MAX($AC11,$AD11)>0,N($S11)>N($Q11)),"Delayed by Task #"&IF($AC11>=$AD11,$D11,$G11)&" (+"&MAX($AC11,$AD11)&"d)","")) | Z11: =IF($B11="","",COUNTIF($D$11:$D$310,$A11)+COUNTIF($G$11:$G$310,$A11)) -> 1 | AA11: =IF($B11="","",IF($AE11="Completed",1,IF($AE11="On Hold",4,IF($AE11="In Progress",2,IF(N($S11)>N($Q11),7,3))))) -> 3 | AB11: =IF($B11="","",IF(OR(AND($D11<>"",ISNUMBER(MATCH($D11,$A$11:$A$310,0))),AND($G11<>"",ISNUMBER(MATCH($G11,$A$11:$A$310,0)))),1,0)) -> 0 | AC11: =IF($D11="",0,N(IFERROR(INDEX($X$11:$X$310,MATCH($D11,$A$11:$A$310,0)),0))) -> 0 | AD11: =IF($G11="",0,N(IFERROR(INDEX($X$11:$X$310,MATCH($G11,$A$11:$A$310,0)),0))) -> 0 | AE11: =IF($B11="","",IF(ISNUMBER($N11),"Completed",IF($L11="Completed","Completed",IF($L11<>"",$L11,IF(ISNUMBER($M11),"In Progress","Not Started"))))) -> Not Started | AF11: =IF($B11="","",IF($AE11="Completed",1,MIN(1,N($O11)))) -> 0 | AG11: =IF(OR($S11="",NOT(ISNUMBER($J11))),"",WORKDAY.INTL($S11,MAX(1,$J11)-1,'Project Info'!$H$12,Holidays!$A$6:$A$205)) -> 46318 | AH11: =IF($B11="","",N($J11)*$AF11) -> 0 | AI11: =IF(ISNUMBER($R11),$R11,0) -> 46318 | AJ11: =IF(ISNUMBER($T11),$T11,0) -> 46318
A12: =IF($B12="","",ROW()-10) -> 2 | B12: REFLECTOR | Mold manufacturing | C12: Tooling | D12: 1 | E12: FS | F12: 0 | J12: 70 | L12: Not Started | Q12: =IF(OR($B12="",'Project Info'!$C$9=""),"",WORKDAY.INTL(MAX('Project Info'!$C$9,N($K12),IF($D12="",0,N(IFERROR(IF($E12="SS",WORKDAY.INTL(INDEX($Q$11:$Q$310,MATCH($D12,$A$11:$A$310,0)),N($F12),'Project Info'!$H$12,Holidays!$A$6:$A$205),IF($E12="FF",WORKDAY.INTL(INDEX($R$11:$R$310,MATCH($D12,$A$11:$A$310,0)),N($F12)-MAX(1,N($J12))+1,'Project Info'!$H$12,Holidays!$A$6:$A$205),WORKDAY.INTL(INDEX($R$11:$R$310,MATCH($D12,$A$11:$A$310,0)),1+N($F12),'Project Info'!$H$12,Holidays!$A$6:$A$205))),0))),IF($G12="",0,N(IFERROR(IF($H12="SS",WORKDAY.INTL(INDEX($Q$11:$Q$310,MATCH($G12,$A$11:$A$310,0)),N($I12),'Project Info'!$H$12,Holidays!$A$6:$A$205),IF($H12="FF",WORKDAY.INTL(INDEX($R$11:$R$310,MATCH($G12,$A$11:$A$310,0)),N($I12)-MAX(1,N($J12))+1,'Project Info'!$H$12,Holidays!$A$6:$A$205),WORKDAY.INTL(INDEX($R$11:$R$310,MATCH($G12,$A$11:$A$310,0)),1+N($I12),'Project Info'!$H$12,Holidays!$A$6:$A$205))),0))))-1,1,'Project Info'!$H$12,Holidays!$A$6:$A$205)) -> 46319 | R12: =IF(OR($Q12="",NOT(ISNUMBER($J12))),"",WORKDAY.INTL($Q12,MAX(1,$J12)-1,'Project Info'!$H$12,Holidays!$A$6:$A$205)) -> 46406 | S12: =IF($Q12="","",IF(ISNUMBER($M12),$M12,WORKDAY.INTL(MAX($Q12,IF($D12="",0,N(IFERROR(IF($E12="SS",WORKDAY.INTL(INDEX($S$11:$S$310,MATCH($D12,$A$11:$A$310,0)),N($F12),'Project Info'!$H$12,Holidays!$A$6:$A$205),IF($E12="FF",WORKDAY.INTL(INDEX($T$11:$T$310,MATCH($D12,$A$11:$A$310,0)),N($F12)-MAX(1,IF(ISNUMBER($P12),$P12,N($J12)))+1,'Project Info'!$H$12,Holidays!$A$6:$A$205),WORKDAY.INTL(INDEX($T$11:$T$310,MATCH($D12,$A$11:$A$310,0)),1+N($F12),'Project Info'!$H$12,Holidays!$A$6:$A$205))),0))),IF($G12="",0,N(IFERROR(IF($H12="SS",WORKDAY.INTL(INDEX($S$11:$S$310,MATCH($G12,$A$11:$A$310,0)),N($I12),'Project Info'!$H$12,Holidays!$A$6:$A$205),IF($H12="FF",WORKDAY.INTL(INDEX($T$11:$T$310,MATCH($G12,$A$11:$A$310,0)),N($I12)-MAX(1,IF(ISNUMBER($P12),$P12,N($J12)))+1,'Project Info'!$H$12,Holidays!$A$6:$A$205),WORKDAY.INTL(INDEX($T$11:$T$310,MATCH($G12,$A$11:$A$310,0)),1+N($I12),'Project Info'!$H$12,Holidays!$A$6:$A$205))),0))),IF($AE12="Completed",0,N('Project Info'!$C$11)))-1,1,'Project Info'!$H$12,Holidays!$A$6:$A$205))) -> 46319 | T12: =IF(OR($S12="",$U12=""),"",IF(ISNUMBER($N12),$N12,WORKDAY.INTL($S12,$U12-1,'Project Info'!$H$12,Holidays!$A$6:$A$205))) -> 46406 | U12: =IF(OR($S12="",NOT(ISNUMBER($J12))),"",IF(ISNUMBER($N12),MAX(1,NETWORKDAYS.INTL($S12,$N12,'Project Info'!$H$12,Holidays!$A$6:$A$205)),MAX(1,IF(ISNUMBER($P12),$P12,$J12),IF(ISNUMBER($M12),NETWORKDAYS.INTL($M12,N('Project Info'!$C$11),'Project Info'!$H$12,Holidays!$A$6:$A$205),0)))) -> 70 | V12: =IF($U12="","",$U12-MAX(1,$J12)) -> 0 | W12: =IF($B12="","",IF($U12="","Enter Duration",IF($AE12="Completed",IF(NOT(ISNUMBER($N12)),"Completed - enter Actual End",IF($V12>0,"Completed - Overshoot",IF($V12<0,"Completed - Early","Completed - On Time"))),IF($AE12="On Hold","On Hold",IF($AE12="In Progress",IF($V12>0,"In Progress - Overshooting","In Progress - On Track"),IF($S12>$Q12,"Delayed Start","Not Started")))))) -> Not Started | X12: =IF(OR(NOT(ISNUMBER($R12)),NOT(ISNUMBER($T12))),"",IF($T12>=$R12,NETWORKDAYS.INTL($R12,$T12,'Project Info'!$H$12,Holidays!$A$6:$A$205)-1,-(NETWORKDAYS.INTL($T12,$R12,'Project Info'!$H$12,Holidays!$A$6:$A$205)-1))) -> 0 | Y12: =IF($B12="","",IF(AND(MAX($AC12,$AD12)>0,N($S12)>N($Q12)),"Delayed by Task #"&IF($AC12>=$AD12,$D12,$G12)&" (+"&MAX($AC12,$AD12)&"d)","")) | Z12: =IF($B12="","",COUNTIF($D$11:$D$310,$A12)+COUNTIF($G$11:$G$310,$A12)) -> 1 | AA12: =IF($B12="","",IF($AE12="Completed",1,IF($AE12="On Hold",4,IF($AE12="In Progress",2,IF(N($S12)>N($Q12),7,3))))) -> 3 | AB12: =IF($B12="","",IF(OR(AND($D12<>"",ISNUMBER(MATCH($D12,$A$11:$A$310,0))),AND($G12<>"",ISNUMBER(MATCH($G12,$A$11:$A$310,0)))),1,0)) -> 1 | AC12: =IF($D12="",0,N(IFERROR(INDEX($X$11:$X$310,MATCH($D12,$A$11:$A$310,0)),0))) -> 0 | AD12: =IF($G12="",0,N(IFERROR(INDEX($X$11:$X$310,MATCH($G12,$A$11:$A$310,0)),0))) -> 0 | AE12: =IF($B12="","",IF(ISNUMBER($N12),"Completed",IF($L12="Completed","Completed",IF($L12<>"",$L12,IF(ISNUMBER($M12),"In Progress","Not Started"))))) -> Not Started | AF12: =IF($B12="","",IF($AE12="Completed",1,MIN(1,N($O12)))) -> 0 | AG12: =IF(OR($S12="",NOT(ISNUMBER($J12))),"",WORKDAY.INTL($S12,MAX(1,$J12)-1,'Project Info'!$H$12,Holidays!$A$6:$A$205)) -> 46406 | AH12: =IF($B12="","",N($J12)*$AF12) -> 0 | AI12: =IF(ISNUMBER($R12),$R12,0) -> 46406 | AJ12: =IF(ISNUMBER($T12),$T12,0) -> 46406
A13: =IF($B13="","",ROW()-10) -> 3 | B13: REFLECTOR | Reflector validation | C13: QA | D13: 2 | E13: FS | F13: 0 | J13: 7 | L13: Not Started | Q13: =IF(OR($B13="",'Project Info'!$C$9=""),"",WORKDAY.INTL(MAX('Project Info'!$C$9,N($K13),IF($D13="",0,N(IFERROR(IF($E13="SS",WORKDAY.INTL(INDEX($Q$11:$Q$310,MATCH($D13,$A$11:$A$310,0)),N($F13),'Project Info'!$H$12,Holidays!$A$6:$A$205),IF($E13="FF",WORKDAY.INTL(INDEX($R$11:$R$310,MATCH($D13,$A$11:$A$310,0)),N($F13)-MAX(1,N($J13))+1,'Project Info'!$H$12,Holidays!$A$6:$A$205),WORKDAY.INTL(INDEX($R$11:$R$310,MATCH($D13,$A$11:$A$310,0)),1+N($F13),'Project Info'!$H$12,Holidays!$A$6:$A$205))),0))),IF($G13="",0,N(IFERROR(IF($H13="SS",WORKDAY.INTL(INDEX($Q$11:$Q$310,MATCH($G13,$A$11:$A$310,0)),N($I13),'Project Info'!$H$12,Holidays!$A$6:$A$205),IF($H13="FF",WORKDAY.INTL(INDEX($R$11:$R$310,MATCH($G13,$A$11:$A$310,0)),N($I13)-MAX(1,N($J13))+1,'Project Info'!$H$12,Holidays!$A$6:$A$205),WORKDAY.INTL(INDEX($R$11:$R$310,MATCH($G13,$A$11:$A$310,0)),1+N($I13),'Project Info'!$H$12,Holidays!$A$6:$A$205))),0))))-1,1,'Project Info'!$H$12,Holidays!$A$6:$A$205)) -> 46407 | R13: =IF(OR($Q13="",NOT(ISNUMBER($J13))),"",WORKDAY.INTL($Q13,MAX(1,$J13)-1,'Project Info'!$H$12,Holidays!$A$6:$A$205)) -> 46414 | S13: =IF($Q13="","",IF(ISNUMBER($M13),$M13,WORKDAY.INTL(MAX($Q13,IF($D13="",0,N(IFERROR(IF($E13="SS",WORKDAY.INTL(INDEX($S$11:$S$310,MATCH($D13,$A$11:$A$310,0)),N($F13),'Project Info'!$H$12,Holidays!$A$6:$A$205),IF($E13="FF",WORKDAY.INTL(INDEX($T$11:$T$310,MATCH($D13,$A$11:$A$310,0)),N($F13)-MAX(1,IF(ISNUMBER($P13),$P13,N($J13)))+1,'Project Info'!$H$12,Holidays!$A$6:$A$205),WORKDAY.INTL(INDEX($T$11:$T$310,MATCH($D13,$A$11:$A$310,0)),1+N($F13),'Project Info'!$H$12,Holidays!$A$6:$A$205))),0))),IF($G13="",0,N(IFERROR(IF($H13="SS",WORKDAY.INTL(INDEX($S$11:$S$310,MATCH($G13,$A$11:$A$310,0)),N($I13),'Project Info'!$H$12,Holidays!$A$6:$A$205),IF($H13="FF",WORKDAY.INTL(INDEX($T$11:$T$310,MATCH($G13,$A$11:$A$310,0)),N($I13)-MAX(1,IF(ISNUMBER($P13),$P13,N($J13)))+1,'Project Info'!$H$12,Holidays!$A$6:$A$205),WORKDAY.INTL(INDEX($T$11:$T$310,MATCH($G13,$A$11:$A$310,0)),1+N($I13),'Project Info'!$H$12,Holidays!$A$6:$A$205))),0))),IF($AE13="Completed",0,N('Project Info'!$C$11)))-1,1,'Project Info'!$H$12,Holidays!$A$6:$A$205))) -> 46407 | T13: =IF(OR($S13="",$U13=""),"",IF(ISNUMBER($N13),$N13,WORKDAY.INTL($S13,$U13-1,'Project Info'!$H$12,Holidays!$A$6:$A$205))) -> 46414 | U13: =IF(OR($S13="",NOT(ISNUMBER($J13))),"",IF(ISNUMBER($N13),MAX(1,NETWORKDAYS.INTL($S13,$N13,'Project Info'!$H$12,Holidays!$A$6:$A$205)),MAX(1,IF(ISNUMBER($P13),$P13,$J13),IF(ISNUMBER($M13),NETWORKDAYS.INTL($M13,N('Project Info'!$C$11),'Project Info'!$H$12,Holidays!$A$6:$A$205),0)))) -> 7 | V13: =IF($U13="","",$U13-MAX(1,$J13)) -> 0 | W13: =IF($B13="","",IF($U13="","Enter Duration",IF($AE13="Completed",IF(NOT(ISNUMBER($N13)),"Completed - enter Actual End",IF($V13>0,"Completed - Overshoot",IF($V13<0,"Completed - Early","Completed - On Time"))),IF($AE13="On Hold","On Hold",IF($AE13="In Progress",IF($V13>0,"In Progress - Overshooting","In Progress - On Track"),IF($S13>$Q13,"Delayed Start","Not Started")))))) -> Not Started | X13: =IF(OR(NOT(ISNUMBER($R13)),NOT(ISNUMBER($T13))),"",IF($T13>=$R13,NETWORKDAYS.INTL($R13,$T13,'Project Info'!$H$12,Holidays!$A$6:$A$205)-1,-(NETWORKDAYS.INTL($T13,$R13,'Project Info'!$H$12,Holidays!$A$6:$A$205)-1))) -> 0 | Y13: =IF($B13="","",IF(AND(MAX($AC13,$AD13)>0,N($S13)>N($Q13)),"Delayed by Task #"&IF($AC13>=$AD13,$D13,$G13)&" (+"&MAX($AC13,$AD13)&"d)","")) | Z13: =IF($B13="","",COUNTIF($D$11:$D$310,$A13)+COUNTIF($G$11:$G$310,$A13)) -> 1 | AA13: =IF($B13="","",IF($AE13="Completed",1,IF($AE13="On Hold",4,IF($AE13="In Progress",2,IF(N($S13)>N($Q13),7,3))))) -> 3 | AB13: =IF($B13="","",IF(OR(AND($D13<>"",ISNUMBER(MATCH($D13,$A$11:$A$310,0))),AND($G13<>"",ISNUMBER(MATCH($G13,$A$11:$A$310,0)))),1,0)) -> 1 | AC13: =IF($D13="",0,N(IFERROR(INDEX($X$11:$X$310,MATCH($D13,$A$11:$A$310,0)),0))) -> 0 | AD13: =IF($G13="",0,N(IFERROR(INDEX($X$11:$X$310,MATCH($G13,$A$11:$A$310,0)),0))) -> 0 | AE13: =IF($B13="","",IF(ISNUMBER($N13),"Completed",IF($L13="Completed","Completed",IF($L13<>"",$L13,IF(ISNUMBER($M13),"In Progress","Not Started"))))) -> Not Started | AF13: =IF($B13="","",IF($AE13="Completed",1,MIN(1,N($O13)))) -> 0 | AG13: =IF(OR($S13="",NOT(ISNUMBER($J13))),"",WORKDAY.INTL($S13,MAX(1,$J13)-1,'Project Info'!$H$12,Holidays!$A$6:$A$205)) -> 46414 | AH13: =IF($B13="","",N($J13)*$AF13) -> 0 | AI13: =IF(ISNUMBER($R13),$R13,0) -> 46414 | AJ13: =IF(ISNUMBER($T13),$T13,0) -> 46414
A14: =IF($B14="","",ROW()-10) -> 4 | B14: REFLECTOR | Production (500 nos @ 35/day) | C14: Production | D14: 3 | E14: FS | F14: 0 | J14: 15 | L14: Not Started | Q14: =IF(OR($B14="",'Project Info'!$C$9=""),"",WORKDAY.INTL(MAX('Project Info'!$C$9,N($K14),IF($D14="",0,N(IFERROR(IF($E14="SS",WORKDAY.INTL(INDEX($Q$11:$Q$310,MATCH($D14,$A$11:$A$310,0)),N($F14),'Project Info'!$H$12,Holidays!$A$6:$A$205),IF($E14="FF",WORKDAY.INTL(INDEX($R$11:$R$310,MATCH($D14,$A$11:$A$310,0)),N($F14)-MAX(1,N($J14))+1,'Project Info'!$H$12,Holidays!$A$6:$A$205),WORKDAY.INTL(INDEX($R$11:$R$310,MATCH($D14,$A$11:$A$310,0)),1+N($F14),'Project Info'!$H$12,Holidays!$A$6:$A$205))),0))),IF($G14="",0,N(IFERROR(IF($H14="SS",WORKDAY.INTL(INDEX($Q$11:$Q$310,MATCH($G14,$A$11:$A$310,0)),N($I14),'Project Info'!$H$12,Holidays!$A$6:$A$205),IF($H14="FF",WORKDAY.INTL(INDEX($R$11:$R$310,MATCH($G14,$A$11:$A$310,0)),N($I14)-MAX(1,N($J14))+1,'Project Info'!$H$12,Holidays!$A$6:$A$205),WORKDAY.INTL(INDEX($R$11:$R$310,MATCH($G14,$A$11:$A$310,0)),1+N($I14),'Project Info'!$H$12,Holidays!$A$6:$A$205))),0))))-1,1,'Project Info'!$H$12,Holidays!$A$6:$A$205)) -> 46415 | R14: =IF(OR($Q14="",NOT(ISNUMBER($J14))),"",WORKDAY.INTL($Q14,MAX(1,$J14)-1,'Project Info'!$H$12,Holidays!$A$6:$A$205)) -> 46431 | S14: =IF($Q14="","",IF(ISNUMBER($M14),$M14,WORKDAY.INTL(MAX($Q14,IF($D14="",0,N(IFERROR(IF($E14="SS",WORKDAY.INTL(INDEX($S$11:$S$310,MATCH($D14,$A$11:$A$310,0)),N($F14),'Project Info'!$H$12,Holidays!$A$6:$A$205),IF($E14="FF",WORKDAY.INTL(INDEX($T$11:$T$310,MATCH($D14,$A$11:$A$310,0)),N($F14)-MAX(1,IF(ISNUMBER($P14),$P14,N($J14)))+1,'Project Info'!$H$12,Holidays!$A$6:$A$205),WORKDAY.INTL(INDEX($T$11:$T$310,MATCH($D14,$A$11:$A$310,0)),1+N($F14),'Project Info'!$H$12,Holidays!$A$6:$A$205))),0))),IF($G14="",0,N(IFERROR(IF($H14="SS",WORKDAY.INTL(INDEX($S$11:$S$310,MATCH($G14,$A$11:$A$310,0)),N($I14),'Project Info'!$H$12,Holidays!$A$6:$A$205),IF($H14="FF",WORKDAY.INTL(INDEX($T$11:$T$310,MATCH($G14,$A$11:$A$310,0)),N($I14)-MAX(1,IF(ISNUMBER($P14),$P14,N($J14)))+1,'Project Info'!$H$12,Holidays!$A$6:$A$205),WORKDAY.INTL(INDEX($T$11:$T$310,MATCH($G14,$A$11:$A$310,0)),1+N($I14),'Project Info'!$H$12,Holidays!$A$6:$A$205))),0))),IF($AE14="Completed",0,N('Project Info'!$C$11)))-1,1,'Project Info'!$H$12,Holidays!$A$6:$A$205))) -> 46415 | T14: =IF(OR($S14="",$U14=""),"",IF(ISNUMBER($N14),$N14,WORKDAY.INTL($S14,$U14-1,'Project Info'!$H$12,Holidays!$A$6:$A$205))) -> 46431 | U14: =IF(OR($S14="",NOT(ISNUMBER($J14))),"",IF(ISNUMBER($N14),MAX(1,NETWORKDAYS.INTL($S14,$N14,'Project Info'!$H$12,Holidays!$A$6:$A$205)),MAX(1,IF(ISNUMBER($P14),$P14,$J14),IF(ISNUMBER($M14),NETWORKDAYS.INTL($M14,N('Project Info'!$C$11),'Project Info'!$H$12,Holidays!$A$6:$A$205),0)))) -> 15 | V14: =IF($U14="","",$U14-MAX(1,$J14)) -> 0 | W14: =IF($B14="","",IF($U14="","Enter Duration",IF($AE14="Completed",IF(NOT(ISNUMBER($N14)),"Completed - enter Actual End",IF($V14>0,"Completed - Overshoot",IF($V14<0,"Completed - Early","Completed - On Time"))),IF($AE14="On Hold","On Hold",IF($AE14="In Progress",IF($V14>0,"In Progress - Overshooting","In Progress - On Track"),IF($S14>$Q14,"Delayed Start","Not Started")))))) -> Not Started | X14: =IF(OR(NOT(ISNUMBER($R14)),NOT(ISNUMBER($T14))),"",IF($T14>=$R14,NETWORKDAYS.INTL($R14,$T14,'Project Info'!$H$12,Holidays!$A$6:$A$205)-1,-(NETWORKDAYS.INTL($T14,$R14,'Project Info'!$H$12,Holidays!$A$6:$A$205)-1))) -> 0 | Y14: =IF($B14="","",IF(AND(MAX($AC14,$AD14)>0,N($S14)>N($Q14)),"Delayed by Task #"&IF($AC14>=$AD14,$D14,$G14)&" (+"&MAX($AC14,$AD14)&"d)","")) | Z14: =IF($B14="","",COUNTIF($D$11:$D$310,$A14)+COUNTIF($G$11:$G$310,$A14)) -> 1 | AA14: =IF($B14="","",IF($AE14="Completed",1,IF($AE14="On Hold",4,IF($AE14="In Progress",2,IF(N($S14)>N($Q14),7,3))))) -> 3 | AB14: =IF($B14="","",IF(OR(AND($D14<>"",ISNUMBER(MATCH($D14,$A$11:$A$310,0))),AND($G14<>"",ISNUMBER(MATCH($G14,$A$11:$A$310,0)))),1,0)) -> 1 | AC14: =IF($D14="",0,N(IFERROR(INDEX($X$11:$X$310,MATCH($D14,$A$11:$A$310,0)),0))) -> 0 | AD14: =IF($G14="",0,N(IFERROR(INDEX($X$11:$X$310,MATCH($G14,$A$11:$A$310,0)),0))) -> 0 | AE14: =IF($B14="","",IF(ISNUMBER($N14),"Completed",IF($L14="Completed","Completed",IF($L14<>"",$L14,IF(ISNUMBER($M14),"In Progress","Not Started"))))) -> Not Started | AF14: =IF($B14="","",IF($AE14="Completed",1,MIN(1,N($O14)))) -> 0 | AG14: =IF(OR($S14="",NOT(ISNUMBER($J14))),"",WORKDAY.INTL($S14,MAX(1,$J14)-1,'Project Info'!$H$12,Holidays!$A$6:$A$205)) -> 46431 | AH14: =IF($B14="","",N($J14)*$AF14) -> 0 | AI14: =IF(ISNUMBER($R14),$R14,0) -> 46431 | AJ14: =IF(ISNUMBER($T14),$T14,0) -> 46431
A15: =IF($B15="","",ROW()-10) -> 5 | B15: REFLECTOR | Finishing & packing (35/day) | C15: Finishing | D15: 4 | E15: FS | F15: 0 | J15: 15 | L15: Not Started | Q15: =IF(OR($B15="",'Project Info'!$C$9=""),"",WORKDAY.INTL(MAX('Project Info'!$C$9,N($K15),IF($D15="",0,N(IFERROR(IF($E15="SS",WORKDAY.INTL(INDEX($Q$11:$Q$310,MATCH($D15,$A$11:$A$310,0)),N($F15),'Project Info'!$H$12,Holidays!$A$6:$A$205),IF($E15="FF",WORKDAY.INTL(INDEX($R$11:$R$310,MATCH($D15,$A$11:$A$310,0)),N($F15)-MAX(1,N($J15))+1,'Project Info'!$H$12,Holidays!$A$6:$A$205),WORKDAY.INTL(INDEX($R$11:$R$310,MATCH($D15,$A$11:$A$310,0)),1+N($F15),'Project Info'!$H$12,Holidays!$A$6:$A$205))),0))),IF($G15="",0,N(IFERROR(IF($H15="SS",WORKDAY.INTL(INDEX($Q$11:$Q$310,MATCH($G15,$A$11:$A$310,0)),N($I15),'Project Info'!$H$12,Holidays!$A$6:$A$205),IF($H15="FF",WORKDAY.INTL(INDEX($R$11:$R$310,MATCH($G15,$A$11:$A$310,0)),N($I15)-MAX(1,N($J15))+1,'Project Info'!$H$12,Holidays!$A$6:$A$205),WORKDAY.INTL(INDEX($R$11:$R$310,MATCH($G15,$A$11:$A$310,0)),1+N($I15),'Project Info'!$H$12,Holidays!$A$6:$A$205))),0))))-1,1,'Project Info'!$H$12,Holidays!$A$6:$A$205)) -> 46433 | R15: =IF(OR($Q15="",NOT(ISNUMBER($J15))),"",WORKDAY.INTL($Q15,MAX(1,$J15)-1,'Project Info'!$H$12,Holidays!$A$6:$A$205)) -> 46449 | S15: =IF($Q15="","",IF(ISNUMBER($M15),$M15,WORKDAY.INTL(MAX($Q15,IF($D15="",0,N(IFERROR(IF($E15="SS",WORKDAY.INTL(INDEX($S$11:$S$310,MATCH($D15,$A$11:$A$310,0)),N($F15),'Project Info'!$H$12,Holidays!$A$6:$A$205),IF($E15="FF",WORKDAY.INTL(INDEX($T$11:$T$310,MATCH($D15,$A$11:$A$310,0)),N($F15)-MAX(1,IF(ISNUMBER($P15),$P15,N($J15)))+1,'Project Info'!$H$12,Holidays!$A$6:$A$205),WORKDAY.INTL(INDEX($T$11:$T$310,MATCH($D15,$A$11:$A$310,0)),1+N($F15),'Project Info'!$H$12,Holidays!$A$6:$A$205))),0))),IF($G15="",0,N(IFERROR(IF($H15="SS",WORKDAY.INTL(INDEX($S$11:$S$310,MATCH($G15,$A$11:$A$310,0)),N($I15),'Project Info'!$H$12,Holidays!$A$6:$A$205),IF($H15="FF",WORKDAY.INTL(INDEX($T$11:$T$310,MATCH($G15,$A$11:$A$310,0)),N($I15)-MAX(1,IF(ISNUMBER($P15),$P15,N($J15)))+1,'Project Info'!$H$12,Holidays!$A$6:$A$205),WORKDAY.INTL(INDEX($T$11:$T$310,MATCH($G15,$A$11:$A$310,0)),1+N($I15),'Project Info'!$H$12,Holidays!$A$6:$A$205))),0))),IF($AE15="Completed",0,N('Project Info'!$C$11)))-1,1,'Project Info'!$H$12,Holidays!$A$6:$A$205))) -> 46433 | T15: =IF(OR($S15="",$U15=""),"",IF(ISNUMBER($N15),$N15,WORKDAY.INTL($S15,$U15-1,'Project Info'!$H$12,Holidays!$A$6:$A$205))) -> 46449 | U15: =IF(OR($S15="",NOT(ISNUMBER($J15))),"",IF(ISNUMBER($N15),MAX(1,NETWORKDAYS.INTL($S15,$N15,'Project Info'!$H$12,Holidays!$A$6:$A$205)),MAX(1,IF(ISNUMBER($P15),$P15,$J15),IF(ISNUMBER($M15),NETWORKDAYS.INTL($M15,N('Project Info'!$C$11),'Project Info'!$H$12,Holidays!$A$6:$A$205),0)))) -> 15 | V15: =IF($U15="","",$U15-MAX(1,$J15)) -> 0 | W15: =IF($B15="","",IF($U15="","Enter Duration",IF($AE15="Completed",IF(NOT(ISNUMBER($N15)),"Completed - enter Actual End",IF($V15>0,"Completed - Overshoot",IF($V15<0,"Completed - Early","Completed - On Time"))),IF($AE15="On Hold","On Hold",IF($AE15="In Progress",IF($V15>0,"In Progress - Overshooting","In Progress - On Track"),IF($S15>$Q15,"Delayed Start","Not Started")))))) -> Not Started | X15: =IF(OR(NOT(ISNUMBER($R15)),NOT(ISNUMBER($T15))),"",IF($T15>=$R15,NETWORKDAYS.INTL($R15,$T15,'Project Info'!$H$12,Holidays!$A$6:$A$205)-1,-(NETWORKDAYS.INTL($T15,$R15,'Project Info'!$H$12,Holidays!$A$6:$A$205)-1))) -> 0 | Y15: =IF($B15="","",IF(AND(MAX($AC15,$AD15)>0,N($S15)>N($Q15)),"Delayed by Task #"&IF($AC15>=$AD15,$D15,$G15)&" (+"&MAX($AC15,$AD15)&"d)","")) | Z15: =IF($B15="","",COUNTIF($D$11:$D$310,$A15)+COUNTIF($G$11:$G$310,$A15)) -> 2 | AA15: =IF($B15="","",IF($AE15="Completed",1,IF($AE15="On Hold",4,IF($AE15="In Progress",2,IF(N($S15)>N($Q15),7,3))))) -> 3 | AB15: =IF($B15="","",IF(OR(AND($D15<>"",ISNUMBER(MATCH($D15,$A$11:$A$310,0))),AND($G15<>"",ISNUMBER(MATCH($G15,$A$11:$A$310,0)))),1,0)) -> 1 | AC15: =IF($D15="",0,N(IFERROR(INDEX($X$11:$X$310,MATCH($D15,$A$11:$A$310,0)),0))) -> 0 | AD15: =IF($G15="",0,N(IFERROR(INDEX($X$11:$X$310,MATCH($G15,$A$11:$A$310,0)),0))) -> 0 | AE15: =IF($B15="","",IF(ISNUMBER($N15),"Completed",IF($L15="Completed","Completed",IF($L15<>"",$L15,IF(ISNUMBER($M15),"In Progress","Not Started"))))) -> Not Started | AF15: =IF($B15="","",IF($AE15="Completed",1,MIN(1,N($O15)))) -> 0 | AG15: =IF(OR($S15="",NOT(ISNUMBER($J15))),"",WORKDAY.INTL($S15,MAX(1,$J15)-1,'Project Info'!$H$12,Holidays!$A$6:$A$205)) -> 46449 | AH15: =IF($B15="","",N($J15)*$AF15) -> 0 | AI15: =IF(ISNUMBER($R15),$R15,0) -> 46449 | AJ15: =IF(ISNUMBER($T15),$T15,0) -> 46449
A16: =IF($B16="","",ROW()-10) -> 6 | B16: REFLECTOR | Dispatch – 8 vehicles (rolling) | C16: Logistics | D16: 5 | E16: SS | F16: 2 | G16: 5 | H16: FF | I16: 1 | J16: 14 | L16: Not Started | Q16: =IF(OR($B16="",'Project Info'!$C$9=""),"",WORKDAY.INTL(MAX('Project Info'!$C$9,N($K16),IF($D16="",0,N(IFERROR(IF($E16="SS",WORKDAY.INTL(INDEX($Q$11:$Q$310,MATCH($D16,$A$11:$A$310,0)),N($F16),'Project Info'!$H$12,Holidays!$A$6:$A$205),IF($E16="FF",WORKDAY.INTL(INDEX($R$11:$R$310,MATCH($D16,$A$11:$A$310,0)),N($F16)-MAX(1,N($J16))+1,'Project Info'!$H$12,Holidays!$A$6:$A$205),WORKDAY.INTL(INDEX($R$11:$R$310,MATCH($D16,$A$11:$A$310,0)),1+N($F16),'Project Info'!$H$12,Holidays!$A$6:$A$205))),0))),IF($G16="",0,N(IFERROR(IF($H16="SS",WORKDAY.INTL(INDEX($Q$11:$Q$310,MATCH($G16,$A$11:$A$310,0)),N($I16),'Project Info'!$H$12,Holidays!$A$6:$A$205),IF($H16="FF",WORKDAY.INTL(INDEX($R$11:$R$310,MATCH($G16,$A$11:$A$310,0)),N($I16)-MAX(1,N($J16))+1,'Project Info'!$H$12,Holidays!$A$6:$A$205),WORKDAY.INTL(INDEX($R$11:$R$310,MATCH($G16,$A$11:$A$310,0)),1+N($I16),'Project Info'!$H$12,Holidays!$A$6:$A$205))),0))))-1,1,'Project Info'!$H$12,Holidays!$A$6:$A$205)) -> 46435 | R16: =IF(OR($Q16="",NOT(ISNUMBER($J16))),"",WORKDAY.INTL($Q16,MAX(1,$J16)-1,'Project Info'!$H$12,Holidays!$A$6:$A$205)) -> 46450 | S16: =IF($Q16="","",IF(ISNUMBER($M16),$M16,WORKDAY.INTL(MAX($Q16,IF($D16="",0,N(IFERROR(IF($E16="SS",WORKDAY.INTL(INDEX($S$11:$S$310,MATCH($D16,$A$11:$A$310,0)),N($F16),'Project Info'!$H$12,Holidays!$A$6:$A$205),IF($E16="FF",WORKDAY.INTL(INDEX($T$11:$T$310,MATCH($D16,$A$11:$A$310,0)),N($F16)-MAX(1,IF(ISNUMBER($P16),$P16,N($J16)))+1,'Project Info'!$H$12,Holidays!$A$6:$A$205),WORKDAY.INTL(INDEX($T$11:$T$310,MATCH($D16,$A$11:$A$310,0)),1+N($F16),'Project Info'!$H$12,Holidays!$A$6:$A$205))),0))),IF($G16="",0,N(IFERROR(IF($H16="SS",WORKDAY.INTL(INDEX($S$11:$S$310,MATCH($G16,$A$11:$A$310,0)),N($I16),'Project Info'!$H$12,Holidays!$A$6:$A$205),IF($H16="FF",WORKDAY.INTL(INDEX($T$11:$T$310,MATCH($G16,$A$11:$A$310,0)),N($I16)-MAX(1,IF(ISNUMBER($P16),$P16,N($J16)))+1,'Project Info'!$H$12,Holidays!$A$6:$A$205),WORKDAY.INTL(INDEX($T$11:$T$310,MATCH($G16,$A$11:$A$310,0)),1+N($I16),'Project Info'!$H$12,Holidays!$A$6:$A$205))),0))),IF($AE16="Completed",0,N('Project Info'!$C$11)))-1,1,'Project Info'!$H$12,Holidays!$A$6:$A$205))) -> 46435 | T16: =IF(OR($S16="",$U16=""),"",IF(ISNUMBER($N16),$N16,WORKDAY.INTL($S16,$U16-1,'Project Info'!$H$12,Holidays!$A$6:$A$205))) -> 46450 | U16: =IF(OR($S16="",NOT(ISNUMBER($J16))),"",IF(ISNUMBER($N16),MAX(1,NETWORKDAYS.INTL($S16,$N16,'Project Info'!$H$12,Holidays!$A$6:$A$205)),MAX(1,IF(ISNUMBER($P16),$P16,$J16),IF(ISNUMBER($M16),NETWORKDAYS.INTL($M16,N('Project Info'!$C$11),'Project Info'!$H$12,Holidays!$A$6:$A$205),0)))) -> 14 | V16: =IF($U16="","",$U16-MAX(1,$J16)) -> 0 | W16: =IF($B16="","",IF($U16="","Enter Duration",IF($AE16="Completed",IF(NOT(ISNUMBER($N16)),"Completed - enter Actual End",IF($V16>0,"Completed - Overshoot",IF($V16<0,"Completed - Early","Completed - On Time"))),IF($AE16="On Hold","On Hold",IF($AE16="In Progress",IF($V16>0,"In Progress - Overshooting","In Progress - On Track"),IF($S16>$Q16,"Delayed Start","Not Started")))))) -> Not Started | X16: =IF(OR(NOT(ISNUMBER($R16)),NOT(ISNUMBER($T16))),"",IF($T16>=$R16,NETWORKDAYS.INTL($R16,$T16,'Project Info'!$H$12,Holidays!$A$6:$A$205)-1,-(NETWORKDAYS.INTL($T16,$R16,'Project Info'!$H$12,Holidays!$A$6:$A$205)-1))) -> 0 | Y16: =IF($B16="","",IF(AND(MAX($AC16,$AD16)>0,N($S16)>N($Q16)),"Delayed by Task #"&IF($AC16>=$AD16,$D16,$G16)&" (+"&MAX($AC16,$AD16)&"d)","")) | Z16: =IF($B16="","",COUNTIF($D$11:$D$310,$A16)+COUNTIF($G$11:$G$310,$A16)) -> 0 | AA16: =IF($B16="","",IF($AE16="Completed",1,IF($AE16="On Hold",4,IF($AE16="In Progress",2,IF(N($S16)>N($Q16),7,3))))) -> 3 | AB16: =IF($B16="","",IF(OR(AND($D16<>"",ISNUMBER(MATCH($D16,$A$11:$A$310,0))),AND($G16<>"",ISNUMBER(MATCH($G16,$A$11:$A$310,0)))),1,0)) -> 1 | AC16: =IF($D16="",0,N(IFERROR(INDEX($X$11:$X$310,MATCH($D16,$A$11:$A$310,0)),0))) -> 0 | AD16: =IF($G16="",0,N(IFERROR(INDEX($X$11:$X$310,MATCH($G16,$A$11:$A$310,0)),0))) -> 0 | AE16: =IF($B16="","",IF(ISNUMBER($N16),"Completed",IF($L16="Completed","Completed",IF($L16<>"",$L16,IF(ISNUMBER($M16),"In Progress","Not Started"))))) -> Not Started | AF16: =IF($B16="","",IF($AE16="Completed",1,MIN(1,N($O16)))) -> 0 | AG16: =IF(OR($S16="",NOT(ISNUMBER($J16))),"",WORKDAY.INTL($S16,MAX(1,$J16)-1,'Project Info'!$H$12,Holidays!$A$6:$A$205)) -> 46450 | AH16: =IF($B16="","",N($J16)*$AF16) -> 0 | AI16: =IF(ISNUMBER($R16),$R16,0) -> 46450 | AJ16: =IF(ISNUMBER($T16),$T16,0) -> 46450
A17: =IF($B17="","",ROW()-10) -> 7 | B17: FEED | Finalize mold design (6 components) | C17: Design | J17: 15 | L17: Not Started | Q17: =IF(OR($B17="",'Project Info'!$C$9=""),"",WORKDAY.INTL(MAX('Project Info'!$C$9,N($K17),IF($D17="",0,N(IFERROR(IF($E17="SS",WORKDAY.INTL(INDEX($Q$11:$Q$310,MATCH($D17,$A$11:$A$310,0)),N($F17),'Project Info'!$H$12,Holidays!$A$6:$A$205),IF($E17="FF",WORKDAY.INTL(INDEX($R$11:$R$310,MATCH($D17,$A$11:$A$310,0)),N($F17)-MAX(1,N($J17))+1,'Project Info'!$H$12,Holidays!$A$6:$A$205),WORKDAY.INTL(INDEX($R$11:$R$310,MATCH($D17,$A$11:$A$310,0)),1+N($F17),'Project Info'!$H$12,Holidays!$A$6:$A$205))),0))),IF($G17="",0,N(IFERROR(IF($H17="SS",WORKDAY.INTL(INDEX($Q$11:$Q$310,MATCH($G17,$A$11:$A$310,0)),N($I17),'Project Info'!$H$12,Holidays!$A$6:$A$205),IF($H17="FF",WORKDAY.INTL(INDEX($R$11:$R$310,MATCH($G17,$A$11:$A$310,0)),N($I17)-MAX(1,N($J17))+1,'Project Info'!$H$12,Holidays!$A$6:$A$205),WORKDAY.INTL(INDEX($R$11:$R$310,MATCH($G17,$A$11:$A$310,0)),1+N($I17),'Project Info'!$H$12,Holidays!$A$6:$A$205))),0))))-1,1,'Project Info'!$H$12,Holidays!$A$6:$A$205)) -> 46310 | R17: =IF(OR($Q17="",NOT(ISNUMBER($J17))),"",WORKDAY.INTL($Q17,MAX(1,$J17)-1,'Project Info'!$H$12,Holidays!$A$6:$A$205)) -> 46328 | S17: =IF($Q17="","",IF(ISNUMBER($M17),$M17,WORKDAY.INTL(MAX($Q17,IF($D17="",0,N(IFERROR(IF($E17="SS",WORKDAY.INTL(INDEX($S$11:$S$310,MATCH($D17,$A$11:$A$310,0)),N($F17),'Project Info'!$H$12,Holidays!$A$6:$A$205),IF($E17="FF",WORKDAY.INTL(INDEX($T$11:$T$310,MATCH($D17,$A$11:$A$310,0)),N($F17)-MAX(1,IF(ISNUMBER($P17),$P17,N($J17)))+1,'Project Info'!$H$12,Holidays!$A$6:$A$205),WORKDAY.INTL(INDEX($T$11:$T$310,MATCH($D17,$A$11:$A$310,0)),1+N($F17),'Project Info'!$H$12,Holidays!$A$6:$A$205))),0))),IF($G17="",0,N(IFERROR(IF($H17="SS",WORKDAY.INTL(INDEX($S$11:$S$310,MATCH($G17,$A$11:$A$310,0)),N($I17),'Project Info'!$H$12,Holidays!$A$6:$A$205),IF($H17="FF",WORKDAY.INTL(INDEX($T$11:$T$310,MATCH($G17,$A$11:$A$310,0)),N($I17)-MAX(1,IF(ISNUMBER($P17),$P17,N($J17)))+1,'Project Info'!$H$12,Holidays!$A$6:$A$205),WORKDAY.INTL(INDEX($T$11:$T$310,MATCH($G17,$A$11:$A$310,0)),1+N($I17),'Project Info'!$H$12,Holidays!$A$6:$A$205))),0))),IF($AE17="Completed",0,N('Project Info'!$C$11)))-1,1,'Project Info'!$H$12,Holidays!$A$6:$A$205))) -> 46310 | T17: =IF(OR($S17="",$U17=""),"",IF(ISNUMBER($N17),$N17,WORKDAY.INTL($S17,$U17-1,'Project Info'!$H$12,Holidays!$A$6:$A$205))) -> 46328 | U17: =IF(OR($S17="",NOT(ISNUMBER($J17))),"",IF(ISNUMBER($N17),MAX(1,NETWORKDAYS.INTL($S17,$N17,'Project Info'!$H$12,Holidays!$A$6:$A$205)),MAX(1,IF(ISNUMBER($P17),$P17,$J17),IF(ISNUMBER($M17),NETWORKDAYS.INTL($M17,N('Project Info'!$C$11),'Project Info'!$H$12,Holidays!$A$6:$A$205),0)))) -> 15 | V17: =IF($U17="","",$U17-MAX(1,$J17)) -> 0 | W17: =IF($B17="","",IF($U17="","Enter Duration",IF($AE17="Completed",IF(NOT(ISNUMBER($N17)),"Completed - enter Actual End",IF($V17>0,"Completed - Overshoot",IF($V17<0,"Completed - Early","Completed - On Time"))),IF($AE17="On Hold","On Hold",IF($AE17="In Progress",IF($V17>0,"In Progress - Overshooting","In Progress - On Track"),IF($S17>$Q17,"Delayed Start","Not Started")))))) -> Not Started | X17: =IF(OR(NOT(ISNUMBER($R17)),NOT(ISNUMBER($T17))),"",IF($T17>=$R17,NETWORKDAYS.INTL($R17,$T17,'Project Info'!$H$12,Holidays!$A$6:$A$205)-1,-(NETWORKDAYS.INTL($T17,$R17,'Project Info'!$H$12,Holidays!$A$6:$A$205)-1))) -> 0 | Y17: =IF($B17="","",IF(AND(MAX($AC17,$AD17)>0,N($S17)>N($Q17)),"Delayed by Task #"&IF($AC17>=$AD17,$D17,$G17)&" (+"&MAX($AC17,$AD17)&"d)","")) | Z17: =IF($B17="","",COUNTIF($D$11:$D$310,$A17)+COUNTIF($G$11:$G$310,$A17)) -> 1 | AA17: =IF($B17="","",IF($AE17="Completed",1,IF($AE17="On Hold",4,IF($AE17="In Progress",2,IF(N($S17)>N($Q17),7,3))))) -> 3 | AB17: =IF($B17="","",IF(OR(AND($D17<>"",ISNUMBER(MATCH($D17,$A$11:$A$310,0))),AND($G17<>"",ISNUMBER(MATCH($G17,$A$11:$A$310,0)))),1,0)) -> 0 | AC17: =IF($D17="",0,N(IFERROR(INDEX($X$11:$X$310,MATCH($D17,$A$11:$A$310,0)),0))) -> 0 | AD17: =IF($G17="",0,N(IFERROR(INDEX($X$11:$X$310,MATCH($G17,$A$11:$A$310,0)),0))) -> 0 | AE17: =IF($B17="","",IF(ISNUMBER($N17),"Completed",IF($L17="Completed","Completed",IF($L17<>"",$L17,IF(ISNUMBER($M17),"In Progress","Not Started"))))) -> Not Started | AF17: =IF($B17="","",IF($AE17="Completed",1,MIN(1,N($O17)))) -> 0 | AG17: =IF(OR($S17="",NOT(ISNUMBER($J17))),"",WORKDAY.INTL($S17,MAX(1,$J17)-1,'Project Info'!$H$12,Holidays!$A$6:$A$205)) -> 46328 | AH17: =IF($B17="","",N($J17)*$AF17) -> 0 | AI17: =IF(ISNUMBER($R17),$R17,0) -> 46328 | AJ17: =IF(ISNUMBER($T17),$T17,0) -> 46328
A18: =IF($B18="","",ROW()-10) -> 8 | B18: FEED | Mold making – Round 1 (Horn, Splitter, Tx Filter) | C18: Tooling | D18: 7 | E18: FS | F18: 0 | J18: 30 | L18: Not Started | Q18: =IF(OR($B18="",'Project Info'!$C$9=""),"",WORKDAY.INTL(MAX('Project Info'!$C$9,N($K18),IF($D18="",0,N(IFERROR(IF($E18="SS",WORKDAY.INTL(INDEX($Q$11:$Q$310,MATCH($D18,$A$11:$A$310,0)),N($F18),'Project Info'!$H$12,Holidays!$A$6:$A$205),IF($E18="FF",WORKDAY.INTL(INDEX($R$11:$R$310,MATCH($D18,$A$11:$A$310,0)),N($F18)-MAX(1,N($J18))+1,'Project Info'!$H$12,Holidays!$A$6:$A$205),WORKDAY.INTL(INDEX($R$11:$R$310,MATCH($D18,$A$11:$A$310,0)),1+N($F18),'Project Info'!$H$12,Holidays!$A$6:$A$205))),0))),IF($G18="",0,N(IFERROR(IF($H18="SS",WORKDAY.INTL(INDEX($Q$11:$Q$310,MATCH($G18,$A$11:$A$310,0)),N($I18),'Project Info'!$H$12,Holidays!$A$6:$A$205),IF($H18="FF",WORKDAY.INTL(INDEX($R$11:$R$310,MATCH($G18,$A$11:$A$310,0)),N($I18)-MAX(1,N($J18))+1,'Project Info'!$H$12,Holidays!$A$6:$A$205),WORKDAY.INTL(INDEX($R$11:$R$310,MATCH($G18,$A$11:$A$310,0)),1+N($I18),'Project Info'!$H$12,Holidays!$A$6:$A$205))),0))))-1,1,'Project Info'!$H$12,Holidays!$A$6:$A$205)) -> 46329 | R18: =IF(OR($Q18="",NOT(ISNUMBER($J18))),"",WORKDAY.INTL($Q18,MAX(1,$J18)-1,'Project Info'!$H$12,Holidays!$A$6:$A$205)) -> 46367 | S18: =IF($Q18="","",IF(ISNUMBER($M18),$M18,WORKDAY.INTL(MAX($Q18,IF($D18="",0,N(IFERROR(IF($E18="SS",WORKDAY.INTL(INDEX($S$11:$S$310,MATCH($D18,$A$11:$A$310,0)),N($F18),'Project Info'!$H$12,Holidays!$A$6:$A$205),IF($E18="FF",WORKDAY.INTL(INDEX($T$11:$T$310,MATCH($D18,$A$11:$A$310,0)),N($F18)-MAX(1,IF(ISNUMBER($P18),$P18,N($J18)))+1,'Project Info'!$H$12,Holidays!$A$6:$A$205),WORKDAY.INTL(INDEX($T$11:$T$310,MATCH($D18,$A$11:$A$310,0)),1+N($F18),'Project Info'!$H$12,Holidays!$A$6:$A$205))),0))),IF($G18="",0,N(IFERROR(IF($H18="SS",WORKDAY.INTL(INDEX($S$11:$S$310,MATCH($G18,$A$11:$A$310,0)),N($I18),'Project Info'!$H$12,Holidays!$A$6:$A$205),IF($H18="FF",WORKDAY.INTL(INDEX($T$11:$T$310,MATCH($G18,$A$11:$A$310,0)),N($I18)-MAX(1,IF(ISNUMBER($P18),$P18,N($J18)))+1,'Project Info'!$H$12,Holidays!$A$6:$A$205),WORKDAY.INTL(INDEX($T$11:$T$310,MATCH($G18,$A$11:$A$310,0)),1+N($I18),'Project Info'!$H$12,Holidays!$A$6:$A$205))),0))),IF($AE18="Completed",0,N('Project Info'!$C$11)))-1,1,'Project Info'!$H$12,Holidays!$A$6:$A$205))) -> 46329 | T18: =IF(OR($S18="",$U18=""),"",IF(ISNUMBER($N18),$N18,WORKDAY.INTL($S18,$U18-1,'Project Info'!$H$12,Holidays!$A$6:$A$205))) -> 46367 | U18: =IF(OR($S18="",NOT(ISNUMBER($J18))),"",IF(ISNUMBER($N18),MAX(1,NETWORKDAYS.INTL($S18,$N18,'Project Info'!$H$12,Holidays!$A$6:$A$205)),MAX(1,IF(ISNUMBER($P18),$P18,$J18),IF(ISNUMBER($M18),NETWORKDAYS.INTL($M18,N('Project Info'!$C$11),'Project Info'!$H$12,Holidays!$A$6:$A$205),0)))) -> 30 | V18: =IF($U18="","",$U18-MAX(1,$J18)) -> 0 | W18: =IF($B18="","",IF($U18="","Enter Duration",IF($AE18="Completed",IF(NOT(ISNUMBER($N18)),"Completed - enter Actual End",IF($V18>0,"Completed - Overshoot",IF($V18<0,"Completed - Early","Completed - On Time"))),IF($AE18="On Hold","On Hold",IF($AE18="In Progress",IF($V18>0,"In Progress - Overshooting","In Progress - On Track"),IF($S18>$Q18,"Delayed Start","Not Started")))))) -> Not Started | X18: =IF(OR(NOT(ISNUMBER($R18)),NOT(ISNUMBER($T18))),"",IF($T18>=$R18,NETWORKDAYS.INTL($R18,$T18,'Project Info'!$H$12,Holidays!$A$6:$A$205)-1,-(NETWORKDAYS.INTL($T18,$R18,'Project Info'!$H$12,Holidays!$A$6:$A$205)-1))) -> 0 | Y18: =IF($B18="","",IF(AND(MAX($AC18,$AD18)>0,N($S18)>N($Q18)),"Delayed by Task #"&IF($AC18>=$AD18,$D18,$G18)&" (+"&MAX($AC18,$AD18)&"d)","")) | Z18: =IF($B18="","",COUNTIF($D$11:$D$310,$A18)+COUNTIF($G$11:$G$310,$A18)) -> 2 | AA18: =IF($B18="","",IF($AE18="Completed",1,IF($AE18="On Hold",4,IF($AE18="In Progress",2,IF(N($S18)>N($Q18),7,3))))) -> 3 | AB18: =IF($B18="","",IF(OR(AND($D18<>"",ISNUMBER(MATCH($D18,$A$11:$A$310,0))),AND($G18<>"",ISNUMBER(MATCH($G18,$A$11:$A$310,0)))),1,0)) -> 1 | AC18: =IF($D18="",0,N(IFERROR(INDEX($X$11:$X$310,MATCH($D18,$A$11:$A$310,0)),0))) -> 0 | AD18: =IF($G18="",0,N(IFERROR(INDEX($X$11:$X$310,MATCH($G18,$A$11:$A$310,0)),0))) -> 0 | AE18: =IF($B18="","",IF(ISNUMBER($N18),"Completed",IF($L18="Completed","Completed",IF($L18<>"",$L18,IF(ISNUMBER($M18),"In Progress","Not Started"))))) -> Not Started | AF18: =IF($B18="","",IF($AE18="Completed",1,MIN(1,N($O18)))) -> 0 | AG18: =IF(OR($S18="",NOT(ISNUMBER($J18))),"",WORKDAY.INTL($S18,MAX(1,$J18)-1,'Project Info'!$H$12,Holidays!$A$6:$A$205)) -> 46367 | AH18: =IF($B18="","",N($J18)*$AF18) -> 0 | AI18: =IF(ISNUMBER($R18),$R18,0) -> 46367 | AJ18: =IF(ISNUMBER($T18),$T18,0) -> 46367
A19: =IF($B19="","",ROW()-10) -> 9 | B19: FEED | Mold making – Round 2 (Rx Filter, Tx/Rx OMT) | C19: Tooling | D19: 8 | E19: FS | F19: 0 | J19: 30 | L19: Not Started | Q19: =IF(OR($B19="",'Project Info'!$C$9=""),"",WORKDAY.INTL(MAX('Project Info'!$C$9,N($K19),IF($D19="",0,N(IFERROR(IF($E19="SS",WORKDAY.INTL(INDEX($Q$11:$Q$310,MATCH($D19,$A$11:$A$310,0)),N($F19),'Project Info'!$H$12,Holidays!$A$6:$A$205),IF($E19="FF",WORKDAY.INTL(INDEX($R$11:$R$310,MATCH($D19,$A$11:$A$310,0)),N($F19)-MAX(1,N($J19))+1,'Project Info'!$H$12,Holidays!$A$6:$A$205),WORKDAY.INTL(INDEX($R$11:$R$310,MATCH($D19,$A$11:$A$310,0)),1+N($F19),'Project Info'!$H$12,Holidays!$A$6:$A$205))),0))),IF($G19="",0,N(IFERROR(IF($H19="SS",WORKDAY.INTL(INDEX($Q$11:$Q$310,MATCH($G19,$A$11:$A$310,0)),N($I19),'Project Info'!$H$12,Holidays!$A$6:$A$205),IF($H19="FF",WORKDAY.INTL(INDEX($R$11:$R$310,MATCH($G19,$A$11:$A$310,0)),N($I19)-MAX(1,N($J19))+1,'Project Info'!$H$12,Holidays!$A$6:$A$205),WORKDAY.INTL(INDEX($R$11:$R$310,MATCH($G19,$A$11:$A$310,0)),1+N($I19),'Project Info'!$H$12,Holidays!$A$6:$A$205))),0))))-1,1,'Project Info'!$H$12,Holidays!$A$6:$A$205)) -> 46368 | R19: =IF(OR($Q19="",NOT(ISNUMBER($J19))),"",WORKDAY.INTL($Q19,MAX(1,$J19)-1,'Project Info'!$H$12,Holidays!$A$6:$A$205)) -> 46403 | S19: =IF($Q19="","",IF(ISNUMBER($M19),$M19,WORKDAY.INTL(MAX($Q19,IF($D19="",0,N(IFERROR(IF($E19="SS",WORKDAY.INTL(INDEX($S$11:$S$310,MATCH($D19,$A$11:$A$310,0)),N($F19),'Project Info'!$H$12,Holidays!$A$6:$A$205),IF($E19="FF",WORKDAY.INTL(INDEX($T$11:$T$310,MATCH($D19,$A$11:$A$310,0)),N($F19)-MAX(1,IF(ISNUMBER($P19),$P19,N($J19)))+1,'Project Info'!$H$12,Holidays!$A$6:$A$205),WORKDAY.INTL(INDEX($T$11:$T$310,MATCH($D19,$A$11:$A$310,0)),1+N($F19),'Project Info'!$H$12,Holidays!$A$6:$A$205))),0))),IF($G19="",0,N(IFERROR(IF($H19="SS",WORKDAY.INTL(INDEX($S$11:$S$310,MATCH($G19,$A$11:$A$310,0)),N($I19),'Project Info'!$H$12,Holidays!$A$6:$A$205),IF($H19="FF",WORKDAY.INTL(INDEX($T$11:$T$310,MATCH($G19,$A$11:$A$310,0)),N($I19)-MAX(1,IF(ISNUMBER($P19),$P19,N($J19)))+1,'Project Info'!$H$12,Holidays!$A$6:$A$205),WORKDAY.INTL(INDEX($T$11:$T$310,MATCH($G19,$A$11:$A$310,0)),1+N($I19),'Project Info'!$H$12,Holidays!$A$6:$A$205))),0))),IF($AE19="Completed",0,N('Project Info'!$C$11)))-1,1,'Project Info'!$H$12,Holidays!$A$6:$A$205))) -> 46368 | T19: =IF(OR($S19="",$U19=""),"",IF(ISNUMBER($N19),$N19,WORKDAY.INTL($S19,$U19-1,'Project Info'!$H$12,Holidays!$A$6:$A$205))) -> 46403 | U19: =IF(OR($S19="",NOT(ISNUMBER($J19))),"",IF(ISNUMBER($N19),MAX(1,NETWORKDAYS.INTL($S19,$N19,'Project Info'!$H$12,Holidays!$A$6:$A$205)),MAX(1,IF(ISNUMBER($P19),$P19,$J19),IF(ISNUMBER($M19),NETWORKDAYS.INTL($M19,N('Project Info'!$C$11),'Project Info'!$H$12,Holidays!$A$6:$A$205),0)))) -> 30 | V19: =IF($U19="","",$U19-MAX(1,$J19)) -> 0 | W19: =IF($B19="","",IF($U19="","Enter Duration",IF($AE19="Completed",IF(NOT(ISNUMBER($N19)),"Completed - enter Actual End",IF($V19>0,"Completed - Overshoot",IF($V19<0,"Completed - Early","Completed - On Time"))),IF($AE19="On Hold","On Hold",IF($AE19="In Progress",IF($V19>0,"In Progress - Overshooting","In Progress - On Track"),IF($S19>$Q19,"Delayed Start","Not Started")))))) -> Not Started | X19: =IF(OR(NOT(ISNUMBER($R19)),NOT(ISNUMBER($T19))),"",IF($T19>=$R19,NETWORKDAYS.INTL($R19,$T19,'Project Info'!$H$12,Holidays!$A$6:$A$205)-1,-(NETWORKDAYS.INTL($T19,$R19,'Project Info'!$H$12,Holidays!$A$6:$A$205)-1))) -> 0 | Y19: =IF($B19="","",IF(AND(MAX($AC19,$AD19)>0,N($S19)>N($Q19)),"Delayed by Task #"&IF($AC19>=$AD19,$D19,$G19)&" (+"&MAX($AC19,$AD19)&"d)","")) | Z19: =IF($B19="","",COUNTIF($D$11:$D$310,$A19)+COUNTIF($G$11:$G$310,$A19)) -> 1 | AA19: =IF($B19="","",IF($AE19="Completed",1,IF($AE19="On Hold",4,IF($AE19="In Progress",2,IF(N($S19)>N($Q19),7,3))))) -> 3 | AB19: =IF($B19="","",IF(OR(AND($D19<>"",ISNUMBER(MATCH($D19,$A$11:$A$310,0))),AND($G19<>"",ISNUMBER(MATCH($G19,$A$11:$A$310,0)))),1,0)) -> 1 | AC19: =IF($D19="",0,N(IFERROR(INDEX($X$11:$X$310,MATCH($D19,$A$11:$A$310,0)),0))) -> 0 | AD19: =IF($G19="",0,N(IFERROR(INDEX($X$11:$X$310,MATCH($G19,$A$11:$A$310,0)),0))) -> 0 | AE19: =IF($B19="","",IF(ISNUMBER($N19),"Completed",IF($L19="Completed","Completed",IF($L19<>"",$L19,IF(ISNUMBER($M19),"In Progress","Not Started"))))) -> Not Started | AF19: =IF($B19="","",IF($AE19="Completed",1,MIN(1,N($O19)))) -> 0 | AG19: =IF(OR($S19="",NOT(ISNUMBER($J19))),"",WORKDAY.INTL($S19,MAX(1,$J19)-1,'Project Info'!$H$12,Holidays!$A$6:$A$205)) -> 46403 | AH19: =IF($B19="","",N($J19)*$AF19) -> 0 | AI19: =IF(ISNUMBER($R19),$R19,0) -> 46403 | AJ19: =IF(ISNUMBER($T19),$T19,0) -> 46403
A20: =IF($B20="","",ROW()-10) -> 10 | B20: FEED | Molding – Round-1 components (1,500 nos) | C20: Molding | D20: 8 | E20: FS | F20: 0 | J20: 4 | L20: Not Started | Q20: =IF(OR($B20="",'Project Info'!$C$9=""),"",WORKDAY.INTL(MAX('Project Info'!$C$9,N($K20),IF($D20="",0,N(IFERROR(IF($E20="SS",WORKDAY.INTL(INDEX($Q$11:$Q$310,MATCH($D20,$A$11:$A$310,0)),N($F20),'Project Info'!$H$12,Holidays!$A$6:$A$205),IF($E20="FF",WORKDAY.INTL(INDEX($R$11:$R$310,MATCH($D20,$A$11:$A$310,0)),N($F20)-MAX(1,N($J20))+1,'Project Info'!$H$12,Holidays!$A$6:$A$205),WORKDAY.INTL(INDEX($R$11:$R$310,MATCH($D20,$A$11:$A$310,0)),1+N($F20),'Project Info'!$H$12,Holidays!$A$6:$A$205))),0))),IF($G20="",0,N(IFERROR(IF($H20="SS",WORKDAY.INTL(INDEX($Q$11:$Q$310,MATCH($G20,$A$11:$A$310,0)),N($I20),'Project Info'!$H$12,Holidays!$A$6:$A$205),IF($H20="FF",WORKDAY.INTL(INDEX($R$11:$R$310,MATCH($G20,$A$11:$A$310,0)),N($I20)-MAX(1,N($J20))+1,'Project Info'!$H$12,Holidays!$A$6:$A$205),WORKDAY.INTL(INDEX($R$11:$R$310,MATCH($G20,$A$11:$A$310,0)),1+N($I20),'Project Info'!$H$12,Holidays!$A$6:$A$205))),0))))-1,1,'Project Info'!$H$12,Holidays!$A$6:$A$205)) -> 46368 | R20: =IF(OR($Q20="",NOT(ISNUMBER($J20))),"",WORKDAY.INTL($Q20,MAX(1,$J20)-1,'Project Info'!$H$12,Holidays!$A$6:$A$205)) -> 46372 | S20: =IF($Q20="","",IF(ISNUMBER($M20),$M20,WORKDAY.INTL(MAX($Q20,IF($D20="",0,N(IFERROR(IF($E20="SS",WORKDAY.INTL(INDEX($S$11:$S$310,MATCH($D20,$A$11:$A$310,0)),N($F20),'Project Info'!$H$12,Holidays!$A$6:$A$205),IF($E20="FF",WORKDAY.INTL(INDEX($T$11:$T$310,MATCH($D20,$A$11:$A$310,0)),N($F20)-MAX(1,IF(ISNUMBER($P20),$P20,N($J20)))+1,'Project Info'!$H$12,Holidays!$A$6:$A$205),WORKDAY.INTL(INDEX($T$11:$T$310,MATCH($D20,$A$11:$A$310,0)),1+N($F20),'Project Info'!$H$12,Holidays!$A$6:$A$205))),0))),IF($G20="",0,N(IFERROR(IF($H20="SS",WORKDAY.INTL(INDEX($S$11:$S$310,MATCH($G20,$A$11:$A$310,0)),N($I20),'Project Info'!$H$12,Holidays!$A$6:$A$205),IF($H20="FF",WORKDAY.INTL(INDEX($T$11:$T$310,MATCH($G20,$A$11:$A$310,0)),N($I20)-MAX(1,IF(ISNUMBER($P20),$P20,N($J20)))+1,'Project Info'!$H$12,Holidays!$A$6:$A$205),WORKDAY.INTL(INDEX($T$11:$T$310,MATCH($G20,$A$11:$A$310,0)),1+N($I20),'Project Info'!$H$12,Holidays!$A$6:$A$205))),0))),IF($AE20="Completed",0,N('Project Info'!$C$11)))-1,1,'Project Info'!$H$12,Holidays!$A$6:$A$205))) -> 46368 | T20: =IF(OR($S20="",$U20=""),"",IF(ISNUMBER($N20),$N20,WORKDAY.INTL($S20,$U20-1,'Project Info'!$H$12,Holidays!$A$6:$A$205))) -> 46372 | U20: =IF(OR($S20="",NOT(ISNUMBER($J20))),"",IF(ISNUMBER($N20),MAX(1,NETWORKDAYS.INTL($S20,$N20,'Project Info'!$H$12,Holidays!$A$6:$A$205)),MAX(1,IF(ISNUMBER($P20),$P20,$J20),IF(ISNUMBER($M20),NETWORKDAYS.INTL($M20,N('Project Info'!$C$11),'Project Info'!$H$12,Holidays!$A$6:$A$205),0)))) -> 4 | V20: =IF($U20="","",$U20-MAX(1,$J20)) -> 0 | W20: =IF($B20="","",IF($U20="","Enter Duration",IF($AE20="Completed",IF(NOT(ISNUMBER($N20)),"Completed - enter Actual End",IF($V20>0,"Completed - Overshoot",IF($V20<0,"Completed - Early","Completed - On Time"))),IF($AE20="On Hold","On Hold",IF($AE20="In Progress",IF($V20>0,"In Progress - Overshooting","In Progress - On Track"),IF($S20>$Q20,"Delayed Start","Not Started")))))) -> Not Started | X20: =IF(OR(NOT(ISNUMBER($R20)),NOT(ISNUMBER($T20))),"",IF($T20>=$R20,NETWORKDAYS.INTL($R20,$T20,'Project Info'!$H$12,Holidays!$A$6:$A$205)-1,-(NETWORKDAYS.INTL($T20,$R20,'Project Info'!$H$12,Holidays!$A$6:$A$205)-1))) -> 0 | Y20: =IF($B20="","",IF(AND(MAX($AC20,$AD20)>0,N($S20)>N($Q20)),"Delayed by Task #"&IF($AC20>=$AD20,$D20,$G20)&" (+"&MAX($AC20,$AD20)&"d)","")) | Z20: =IF($B20="","",COUNTIF($D$11:$D$310,$A20)+COUNTIF($G$11:$G$310,$A20)) -> 2 | AA20: =IF($B20="","",IF($AE20="Completed",1,IF($AE20="On Hold",4,IF($AE20="In Progress",2,IF(N($S20)>N($Q20),7,3))))) -> 3 | AB20: =IF($B20="","",IF(OR(AND($D20<>"",ISNUMBER(MATCH($D20,$A$11:$A$310,0))),AND($G20<>"",ISNUMBER(MATCH($G20,$A$11:$A$310,0)))),1,0)) -> 1 | AC20: =IF($D20="",0,N(IFERROR(INDEX($X$11:$X$310,MATCH($D20,$A$11:$A$310,0)),0))) -> 0 | AD20: =IF($G20="",0,N(IFERROR(INDEX($X$11:$X$310,MATCH($G20,$A$11:$A$310,0)),0))) -> 0 | AE20: =IF($B20="","",IF(ISNUMBER($N20),"Completed",IF($L20="Completed","Completed",IF($L20<>"",$L20,IF(ISNUMBER($M20),"In Progress","Not Started"))))) -> Not Started | AF20: =IF($B20="","",IF($AE20="Completed",1,MIN(1,N($O20)))) -> 0 | AG20: =IF(OR($S20="",NOT(ISNUMBER($J20))),"",WORKDAY.INTL($S20,MAX(1,$J20)-1,'Project Info'!$H$12,Holidays!$A$6:$A$205)) -> 46372 | AH20: =IF($B20="","",N($J20)*$AF20) -> 0 | AI20: =IF(ISNUMBER($R20),$R20,0) -> 46372 | AJ20: =IF(ISNUMBER($T20),$T20,0) -> 46372
A21: =IF($B21="","",ROW()-10) -> 11 | B21: FEED | Molding – Round-2 components (1,500 nos) | C21: Molding | D21: 9 | E21: FS | F21: 0 | G21: 10 | H21: FS | I21: 0 | J21: 4 | L21: Not Started | Q21: =IF(OR($B21="",'Project Info'!$C$9=""),"",WORKDAY.INTL(MAX('Project Info'!$C$9,N($K21),IF($D21="",0,N(IFERROR(IF($E21="SS",WORKDAY.INTL(INDEX($Q$11:$Q$310,MATCH($D21,$A$11:$A$310,0)),N($F21),'Project Info'!$H$12,Holidays!$A$6:$A$205),IF($E21="FF",WORKDAY.INTL(INDEX($R$11:$R$310,MATCH($D21,$A$11:$A$310,0)),N($F21)-MAX(1,N($J21))+1,'Project Info'!$H$12,Holidays!$A$6:$A$205),WORKDAY.INTL(INDEX($R$11:$R$310,MATCH($D21,$A$11:$A$310,0)),1+N($F21),'Project Info'!$H$12,Holidays!$A$6:$A$205))),0))),IF($G21="",0,N(IFERROR(IF($H21="SS",WORKDAY.INTL(INDEX($Q$11:$Q$310,MATCH($G21,$A$11:$A$310,0)),N($I21),'Project Info'!$H$12,Holidays!$A$6:$A$205),IF($H21="FF",WORKDAY.INTL(INDEX($R$11:$R$310,MATCH($G21,$A$11:$A$310,0)),N($I21)-MAX(1,N($J21))+1,'Project Info'!$H$12,Holidays!$A$6:$A$205),WORKDAY.INTL(INDEX($R$11:$R$310,MATCH($G21,$A$11:$A$310,0)),1+N($I21),'Project Info'!$H$12,Holidays!$A$6:$A$205))),0))))-1,1,'Project Info'!$H$12,Holidays!$A$6:$A$205)) -> 46405 | R21: =IF(OR($Q21="",NOT(ISNUMBER($J21))),"",WORKDAY.INTL($Q21,MAX(1,$J21)-1,'Project Info'!$H$12,Holidays!$A$6:$A$205)) -> 46408 | S21: =IF($Q21="","",IF(ISNUMBER($M21),$M21,WORKDAY.INTL(MAX($Q21,IF($D21="",0,N(IFERROR(IF($E21="SS",WORKDAY.INTL(INDEX($S$11:$S$310,MATCH($D21,$A$11:$A$310,0)),N($F21),'Project Info'!$H$12,Holidays!$A$6:$A$205),IF($E21="FF",WORKDAY.INTL(INDEX($T$11:$T$310,MATCH($D21,$A$11:$A$310,0)),N($F21)-MAX(1,IF(ISNUMBER($P21),$P21,N($J21)))+1,'Project Info'!$H$12,Holidays!$A$6:$A$205),WORKDAY.INTL(INDEX($T$11:$T$310,MATCH($D21,$A$11:$A$310,0)),1+N($F21),'Project Info'!$H$12,Holidays!$A$6:$A$205))),0))),IF($G21="",0,N(IFERROR(IF($H21="SS",WORKDAY.INTL(INDEX($S$11:$S$310,MATCH($G21,$A$11:$A$310,0)),N($I21),'Project Info'!$H$12,Holidays!$A$6:$A$205),IF($H21="FF",WORKDAY.INTL(INDEX($T$11:$T$310,MATCH($G21,$A$11:$A$310,0)),N($I21)-MAX(1,IF(ISNUMBER($P21),$P21,N($J21)))+1,'Project Info'!$H$12,Holidays!$A$6:$A$205),WORKDAY.INTL(INDEX($T$11:$T$310,MATCH($G21,$A$11:$A$310,0)),1+N($I21),'Project Info'!$H$12,Holidays!$A$6:$A$205))),0))),IF($AE21="Completed",0,N('Project Info'!$C$11)))-1,1,'Project Info'!$H$12,Holidays!$A$6:$A$205))) -> 46405 | T21: =IF(OR($S21="",$U21=""),"",IF(ISNUMBER($N21),$N21,WORKDAY.INTL($S21,$U21-1,'Project Info'!$H$12,Holidays!$A$6:$A$205))) -> 46408 | U21: =IF(OR($S21="",NOT(ISNUMBER($J21))),"",IF(ISNUMBER($N21),MAX(1,NETWORKDAYS.INTL($S21,$N21,'Project Info'!$H$12,Holidays!$A$6:$A$205)),MAX(1,IF(ISNUMBER($P21),$P21,$J21),IF(ISNUMBER($M21),NETWORKDAYS.INTL($M21,N('Project Info'!$C$11),'Project Info'!$H$12,Holidays!$A$6:$A$205),0)))) -> 4 | V21: =IF($U21="","",$U21-MAX(1,$J21)) -> 0 | W21: =IF($B21="","",IF($U21="","Enter Duration",IF($AE21="Completed",IF(NOT(ISNUMBER($N21)),"Completed - enter Actual End",IF($V21>0,"Completed - Overshoot",IF($V21<0,"Completed - Early","Completed - On Time"))),IF($AE21="On Hold","On Hold",IF($AE21="In Progress",IF($V21>0,"In Progress - Overshooting","In Progress - On Track"),IF($S21>$Q21,"Delayed Start","Not Started")))))) -> Not Started | X21: =IF(OR(NOT(ISNUMBER($R21)),NOT(ISNUMBER($T21))),"",IF($T21>=$R21,NETWORKDAYS.INTL($R21,$T21,'Project Info'!$H$12,Holidays!$A$6:$A$205)-1,-(NETWORKDAYS.INTL($T21,$R21,'Project Info'!$H$12,Holidays!$A$6:$A$205)-1))) -> 0 | Y21: =IF($B21="","",IF(AND(MAX($AC21,$AD21)>0,N($S21)>N($Q21)),"Delayed by Task #"&IF($AC21>=$AD21,$D21,$G21)&" (+"&MAX($AC21,$AD21)&"d)","")) | Z21: =IF($B21="","",COUNTIF($D$11:$D$310,$A21)+COUNTIF($G$11:$G$310,$A21)) -> 1 | AA21: =IF($B21="","",IF($AE21="Completed",1,IF($AE21="On Hold",4,IF($AE21="In Progress",2,IF(N($S21)>N($Q21),7,3))))) -> 3 | AB21: =IF($B21="","",IF(OR(AND($D21<>"",ISNUMBER(MATCH($D21,$A$11:$A$310,0))),AND($G21<>"",ISNUMBER(MATCH($G21,$A$11:$A$310,0)))),1,0)) -> 1 | AC21: =IF($D21="",0,N(IFERROR(INDEX($X$11:$X$310,MATCH($D21,$A$11:$A$310,0)),0))) -> 0 | AD21: =IF($G21="",0,N(IFERROR(INDEX($X$11:$X$310,MATCH($G21,$A$11:$A$310,0)),0))) -> 0 | AE21: =IF($B21="","",IF(ISNUMBER($N21),"Completed",IF($L21="Completed","Completed",IF($L21<>"",$L21,IF(ISNUMBER($M21),"In Progress","Not Started"))))) -> Not Started | AF21: =IF($B21="","",IF($AE21="Completed",1,MIN(1,N($O21)))) -> 0 | AG21: =IF(OR($S21="",NOT(ISNUMBER($J21))),"",WORKDAY.INTL($S21,MAX(1,$J21)-1,'Project Info'!$H$12,Holidays!$A$6:$A$205)) -> 46408 | AH21: =IF($B21="","",N($J21)*$AF21) -> 0 | AI21: =IF(ISNUMBER($R21),$R21,0) -> 46408 | AJ21: =IF(ISNUMBER($T21),$T21,0) -> 46408
